<?xml version="1.0"?>
<robot name="myrobot" xmlns:xacro="http://www.ros.org/wiki/xacro">

  <!-- Include the Gazebo configuration -->
  <xacro:include filename="$(find lab_4)/urdf/my_robot.gazebo"/>
  

  <!-- Dummy link to resolve root link inertia warning -->
  <link name="dummy_link">
    <inertial>
      <mass value="0.0001" />
      <origin xyz="0 0 0" />
      <inertia ixx="0.0001" ixy="0" ixz="0" iyy="0.0001" iyz="0" izz="0.0001" />
    </inertial>
  </link>

  <joint name="base_joint" type="fixed">
    <parent link="dummy_link" />
    <child link="chassis" />
  </joint>

  <!-- Chassis link -->
  <link name="chassis">
    <inertial>
      <mass value="5.0" />
      <origin xyz="0.0 0 0.1" rpy="0 0 0" />
      <inertia ixx="0.1" ixy="0" ixz="0" iyy="0.1" iyz="0" izz="0.1" />
    </inertial>
    <collision name="collision">
      <geometry>
        <box size=".4 .2 .1" />
      </geometry>
    </collision>
    <visual name="chassis_visual">
      <origin xyz="0 0 0" rpy="0 0 0" />
      <geometry>
        <box size=".4 .2 .1" />
      </geometry>
      <material name="blue">
        <color rgba="0.0 0.0 1 1.0" />
      </material>
    </visual>
    <collision name="caster_collision">
      <origin xyz="-0.15 0 -0.05" rpy="0 0 0" />
      <geometry>
        <sphere radius="0.05" />
      </geometry>
    </collision>
    <visual name="caster_visual">
      <origin xyz="-0.15 0 -0.05" rpy="0 0 0" />
      <geometry>
        <sphere radius="0.05" />
      </geometry>
    </visual>
    <collision name="caster_front_collision">
      <origin xyz="0.15 0 -0.05" rpy="0 0 0" />
      <geometry>
        <sphere radius="0.05" />
      </geometry>
    </collision>
    <visual name="caster_front_visual">
      <origin xyz="0.15 0 -0.05" rpy="0 0 0" />
      <geometry>
        <sphere radius="0.05" />
      </geometry>
    </visual>
  </link>

  <!-- Left wheel link -->
  <link name="left_wheel">
    <collision name="collision">
      <origin xyz="0 0 0" rpy="0 1.5707 1.5707" />
      <geometry>
        <cylinder radius="0.1" length="0.05" />
      </geometry>
    </collision>
    <visual name="left_wheel_visual">
      <origin xyz="0 0 0" rpy="0 1.5707 1.5707" />
      <geometry>
        <cylinder radius="0.1" length="0.05" />
      </geometry>
      <material name="red">
        <color rgba="1 0.0 0.0 1.0" />
      </material>
    </visual>
    <inertial>
      <origin xyz="0 0 0" rpy="0 1.5707 1.5707" />
      <mass value="5" />
      <inertia ixx="0.1" ixy="0.0" ixz="0.0" iyy="0.1" iyz="0.0" izz="0.1" />
    </inertial>
  </link>

  <!-- Right wheel link -->
  <link name="right_wheel">
    <collision name="collision">
      <origin xyz="0 0 0" rpy="0 1.5707 1.5707" />
      <geometry>
        <cylinder radius="0.1" length="0.05" />
      </geometry>
    </collision>
    <visual name="right_wheel_visual">
      <origin xyz="0 0 0" rpy="0 1.5707 1.5707" />
      <geometry>
        <cylinder radius="0.1" length="0.05" />
      </geometry>
      <material name="green">
        <color rgba="0.0 1 0.0 1.0" />
      </material>
    </visual>
    <inertial>
      <origin xyz="0 0 0" rpy="0 1.5707 1.5707" />
      <mass value="5" />
      <inertia ixx="0.1" ixy="0.0" ixz="0.0" iyy="0.1" iyz="0.0" izz="0.1" />
    </inertial>
  </link>

  <!-- Joints connecting wheels to chassis -->
  <joint type="continuous" name="left_wheel_hinge">
    <origin xyz="0 0.15 0" rpy="0 0 0" />
    <parent link="chassis" />
    <child link="left_wheel" />
    <axis xyz="0 1 0" />
  </joint>

  <joint type="continuous" name="right_wheel_hinge">
    <origin xyz="0 -0.15 0" rpy="0 0 0" />
    <parent link="chassis" />
    <child link="right_wheel" />
    <axis xyz="0 1 0" />
  </joint>

  <!-- Hokuyo Laser -->
  <link name="hokuyo_link">
    <collision>
      <origin xyz="0 0 0" rpy="0 0 0" />
      <geometry>
        <box size="0.1 0.1 0.1" />
      </geometry>
    </collision>
    <visual>
      <origin xyz="0 0 0" rpy="0 0 0" />
      <geometry>
        <mesh filename="package://lab_4/meshes/hokuyo.dae" />
      </geometry>
    </visual>
    <inertial>
      <mass value="1e-5" />
      <origin xyz="0 0 0" rpy="0 0 0" />
      <inertia ixx="1e-6" ixy="0" ixz="0" iyy="1e-6" iyz="0" izz="1e-6" />
    </inertial>
  </link>

  <joint name="hokuyo_joint" type="fixed">
    <axis xyz="0 1 0" />
    <origin xyz="0.15 0 0.1" rpy="0 0 0" />
    <parent link="chassis" />
    <child link="hokuyo_link" />
  </joint>

</robot>
